Workbook

Sheet 개정이력
A1: 개정 이력
A2: 버전 | B2: 변경일 | C2: 변경 사유 | D2: 관련시트 | E2: 변경 내용 | F2: 작성자 | G2: 승인
A3: 1.0 | B3: 2024.09.10 | C3: 최초 작성 및 배포 | E3: 최초 작성 및 배포 | F3: 홍수민
A4: 1.1 | B4: 2024.09.19 | C4: 수식 오류 개선 및 정규표현식 일원화 | D4: "Ⅲ.품질진단 컬럼_규칙_결과" | E4: 엑셀 수식 수정, 정규표현식 숫자형태 \d => [0-9] 로 통일 사망일자 관련 선후관계유효성 로직 수정(CASE WHEN NOT EXISTS -> JOIN 방식으로 변경) 방문일자 관련 선후관계유효성 로직 수정(CASE WHEN NOT EXISTS -> JOIN 방식으로 변경) | F4: 홍수민

Sheet 시트별 작성가이드
A1: Owner Ship | B1: Sheet명 | C1: 항목명 | F1: 설명 | G1: 병원별 입력필요
A2: 사업단 | B2: Ⅰ.품질진단 기준 | C2: 품질진단 기준 | F2: 품질진단을 위한 기준 | G2: N
A3: 사업단 | B3: Ⅱ.품질진단 테이블 | C3: 1.테이블 정의 | D3: 데이터 분류 | E3: 대분류 | F3: 테이블의 대분류(예: Baseline DB 등) | G3: N
E4: 버전 | F4: CDM 버전(예: 5.3.1, 5.4 등) | G4: Y
E5: 주제분류 | F5: 테이블의 중분류(예: Clinical Data 등) | G5: N
D6: 테이블 정보 | E6: 한글테이블명 | F6: 테이블 한글명 | G6: N
E7: 영문테이블명 | F7: 테이블 영문명 | G7: 필요시
D8: 진단 정보 | E8: 진단대상여부 | F8: 테이블의 품질진단 대상 선정 여부 (예- Y, N) | G8: N
E9: 대상제외사유 | F9: 품질진단 대상 제외 사유 (예: 로그, 백업, 시스템관리용) | G9: N
E10: 진단범위 | F10: 테이블에 대한 진단 범위 (예: 전수, 부분 | G10: N
E11: DBMS 종류 | F11: DBMS 종류(예 Oracle, MySql, DB2 등), NoSQL(MongGo DB, Neo4j, Redis 등) | G11: 필요시
A12: 사업단/병원 | B12: Ⅲ.품질진단 컬럼_규칙_결과 | C12: 1.컬럼 정의 | D12: 데이터 분류 | E12: 버전 | F12: CDM 버전(예: 5.3.1, 5.4 등) | G12: Y
E13: 대분류 | F13: 테이블의 대분류(예: Baseline DB 등) | G13: N
E14: 주제분류 | F14: 테이블의 중분류(예: Clinical Data 등) | G14: N
D15: 테이블 정보 | E15: 스키마명 | F15: 테이블 스키마명 | G15: Y
E16: 한글테이블명 | F16: 테이블 한글명 | G16: N
E17: 영문테이블명 | F17: 테이블 영문명 | G17: 필요시
D18: 컬럼 정보 | E18: 한글컬럼명 | F18: 컬럼의 한글명 | G18: N
E19: 영문컬럼명 | F19: 컬럼의 영문명 | G19: N
E20: 컬럼타입(길이) | F20: 컬럼의 데이터 타입과 길이 | G20: N
E21: PK | F21: PK정의(예: PK1, PK2) | G21: N
E22: 도메인명 | F22: 컬럼의 도메인 명 | G22: N
E23: 설명 | F23: 컬럼의 설명 | G23: N
E24: 값 | F24: (샘플)컬럼의 데이터 값 | G24: N
E25: 항목명 | F25: 항목정의서의 항목명 | G25: N
E26: 비고 | F26: 데이터의 필수/필수아님 여부 | G26: N
E27: NOT NULL 여부 | F27: Not Null 여부 (Not Null -> Y , Null -> N) | G27: N
C28: 2.진단규칙 정의 | D28: 진단대상 정보 | E28: 진단NO | F28: 품질진단 일련번호 | G28: N
E29: 상세지표 | F29: 컬럼별 적용 품질상세지표 | G29: N
E30: 진단대상 여부④ | F30: 컬럼의 품질진단 대상 여부 (예- Y, N) | G30: 필요시
E31: 진단대상 제외사유⑤ | F31: 진단대상 제외사유 | G31: 필요시
D32: 진단 정보 | E32: 진단유형 | F32: 컬럼별 적용 진단유형 | G32: N
E33: 진단규칙내용 | F33: 품질진단을 수행 할 내용. 이 내용을 기반으로 진단SQL(스크립트)을 작성 | G33: N
E34: 코드테이블 스키마명 | F34: 코드테이블의 스키마명 | G34: Y
E35: 코드테이블명 | F35: 코드테이블명 | G35: 필요시
E36: 코드명(참조) | F36: 코드테이블의 컬럼명 | G36: N
E37: 코드값(참조) | F37: 코드테이블 컬럼의 검색 SQL 규칙 | G37: N
E38: 참조테이블명 | F38: FK 참조 테이블명 | G38: N
E39: 참조컬럼명 | F39: FK 참조 테이블의 컬럼명 | G39: N
E40: 최소값 | F40: 정상 허용범위 최소값 | G40: N
...

Sheet Ⅰ.품질진단기준
A1: 지표 | B1: 정의 | C1: 상세지표 | D1: 정의 | E1: 진단대상 | F1: 진단방법 | G1: 적용단계
A2: 일관성 (Consistency) | B2: 같은 의미를 갖는 데이터는 표준을 준수하여 동일한 용어와 도메인으로 정의하고 중복 ,연계 데이터의 값이 서로 일치하는지 진단하는 지표 | C2: 참조무결성 | D2: FK 관계에 있는 테이블 간 참조무결성이 유지되는지 진단하는 지표 | E2: 값 | F2: 업무규칙진단, 체크리스트 | G2: 구축단계
C3: 중복 일관성 | D3: 업무 목적에 따라 중복 데이터를 생성한 경우 각각의 중복 컬럼 값이 일치하는지 진단하는 지표 | E3: 값 | F3: 업무규칙진단, 체크리스트 | G3: 구축단계
C4: 표준 일관성 | D4: 동일한 데이터가 표준을 준수하여 형식(도메인)과 명칭(표준용어)이 일치하는지 진단하는 지표 | E4: 구조 | F4: 업무규칙진단, 체크리스트 | G4: 구축단계
C5: 연계 일관성 | D5: 원천 테이블과 연계 목적의 복제테이블이 같은 시점에 데이터 값이 일치하는지 진단하는 지표 | E5: 값 | F5: 체크리스트 | G5: 구축단계
A6: 정확성 (Anccuracy) | B6: 데이터가 실 세계 사실 및 업무규칙에 따라 정해진 유효범위를 충족하며, 정확한 값이 저장되어 있는지를 진단하는 지표 | C6: 논리관계 정확성 | D6: 논리관계가 있는 항목에 대해 논리에 맞게 값이 관리되고 있는지 진단하는 지표 | E6: 값 | F6: 업무규칙진단, 체크리스트 | G6: 구축단계
C7: 파생항목 정확성 | D7: 원천항목값과 파생된 항목값이 정확하게 일치하는지 진단하는 지표 | E7: 값 | F7: 업무규칙진단, 체크리스트 | G7: 구축단계
C8: 메타 정확성 | D8: 이미지, 동영상 등 비정형 데이터의 메터 속성데이터가 실체 콘텐츠의 정보와 일치하는지 진단하는 지표 | E8: 값 | F8: 업무규칙진단(별도의 비정형 진단 도구 필요), 체크리스트 | G8: 구축단계
A9: 보안성 (Security) | B9: 데이터 관리 주체가 관리되고 외부 및 내부 요인으로부터 데이터를 보호하기 위해 접근이 적절히 통제되며 개인정보 등 주요 데이터에 대하여 보호 조치가 이루어져 있는지 진단하는 지표 | C9: 정보 보호성 | D9: 개인정보보호(비식별화조치)와 외부의 침입 및 정보 훼손을 방지하는 절차와 규정을 수립하고 수행하고 있는지 진단하는 지표 | E9: 관리체계 | F9: 체크리스트 | G9: 구축단계
C10: 통제성 | D10: 단일 테이블 내에서 시계열적 선후관계가 업무 규칙으로 정의된 경우 발생 업무 규칙을 준수하는지 진단하는 지표 | E10: 관리체계 | F10: 체크리스트 | G10: 구축단계
C11: 데이터 관리 책임성 | D11: 사용자 접근 권한과 책임을 명확히 부여하고 관리하는지 진단하는 지표 | E11: 관리체계 | F11: 체크리스트 | G11: 구축단계
A12: 완전성 (Completeness) | B12: 데이터의 저장소인 데이터베이스를 구축함에 있어 논리적인 설계와 물리적인 구조를 갖추고, 업무 요건에 맞게 데이터가 저장되는지를 진단하는 지표 | C12: 단독 완전성 | D12: 데이터가 업무 요건에 맞게 항상 채워져 있는지 진단하는 지표 | E12: 값 | F12: 업무규칙진단, 체크리스트 | G12: 구축단계
C13: 조건 완전성 | D13: 데이터가 다른 데이터 항목의 업무 조건에 따라 항상 채워져 있는지 진단하는 지표 (Conditional Not Null) | E13: 값 | F13: 업무규칙진단, 체크리스트 | G13: 구축단계
C14: 구조 완전성 | D14: 데이터모델이 데이터구조 관리 지침을 준수하고 있는지 진단하는 지표 | E14: 구조 | F14: 체크리스트 | G14: 구축단계
A15: 유효성 (Validity) | B15: 데이터가 의도한 범위와 형식으로 구성되어 해당 범위와 형식에 벗어나지 않고 본래의 효과를 제공하며 추적 가능한지 진단하는 지표 | C15: 범위 유효성 | D15: 값이 특정 리스트 내에 존재하여야 하거나, 정해진 범위 내에 존재하는지 진단하는 지표 | E15: 값 | F15: 프로파일링진단, 체크리스트 | G15: 구축단계
C16: 날짜 유효성 | D16: 항목이 일자일 경우 값은 유효한 일시의 값을 갖는지 진단하는 지표 | E16: 값 | F16: 프로파일링진단, 체크리스트 | G16: 구축단계
C17: 형식 유효성 | D17: 정해진 형식(Format)에 맞게 값이 존재하고 있는지 진단하는 지표 | E17: 값 | F17: 프로파일링진단, 체크리스트 | G17: 구축단계
C18: 코드 유효성 | D18: 표준코드에 정의된 유효 코드값을 갖는지 진단하는 지표 | E18: 값 | F18: 프로파일링진단, 체크리스트 | G18: 구축단계
C19: 여부 유효성 | D19: 여부 항목의 값이 정해진 값의 범위에서 관리되고 있는지 진단하는 지표 | E19: 값 | F19: 프로파일링진단, 체크리스트 | G19: 구축단계
C20: 선후관계 유효성 | D20: 복수의 컬럼값이 선후 관계에 있을 경우 발생업무 규칙을 지키는지 진단하는 지표 | E20: 값 | F20: 프로파일링진단, 체크리스트 | G20: 구축단계
A21: 준비성 (Preparation) | B21: 데이터 품질관리를 위해 기본적으로 관리해야 하는 정책, 규정, 조직, 절차 등을 마련하고, 최신의 내용으로 충실하게 관리되는지를 진단하는 지표 | C21: 체계 구비성 | D21: 데이터 품질 관리를 위한 기본적인 요소들이 체계적으로 수립되어 관리되는지 진단하는 지표 | E21: 관리체계 | F21: 체크리스트 | G21: 구축단계
C22: 체계 준수성 | D22: 수립된 데이터 품질관리 기준 요소들이 체계적으로 수행하는지 진단하는 지표 | E22: 관리체계 | F22: 체크리스트 | G22: 구축단계
A23: 유용성 (Relevance) | B23: 사용자가 만족하는 수준의 충분한 정보가 수집되고 제공되는지, 사용자의 정보 이용에 만족도를 충족하는지, 데이터의 범위와 상세화 정도를 충족시키는지를 진단하는 지표 | C23: 충분성 | D23: 사용자의 요구 사항을 충분히 충족 시킬 수 있는지 진단하는 지표 | E23: 관리체계 | F23: 체크리스트 | G23: 운영단계
C24: 유연성 | D24: 사용자의 요구 사항을 수용할 수 있는지 진단하는 지표 | E24: 관리체계 | F24: 체크리스트 | G24: 운영단계
C25: 활용성 | D25: 실제 공급되는 데이터를 사용자가 활용하는지를 진단하는 지표 | E25: 관리체계 | F25: 체크리스트 | G25: 운영단계
C26: 추적성 | D26: 데이터의 변경 내역이 관리되고 있음 | E26: 관리체계 | F26: 체크리스트 | G26: 운영단계
A27: 접근성 (Accessibility) | B27: 사용자가 원하는 데이터를 손쉽게 사용할 수 있는지 진단하는 지표 | C27: 검색 용이성 | D27: 사용자가 원하는 데이터를 검색할 때 데이터 로딩속도, 원하는 데이터 획득, 용이한 데이터 접근 등 데이터 검색 만족도를 진단하는 지표 | E27: 관리체계 | F27: 체크리스트 | G27: 운영단계
C28: 사용 편의성 | D28: 사용자 데이터를 사용할 때, 다양한 요구사항을 만족 시킬 수 있는 서비스 및 데이터 유형이 제공되고 있는지 진단하는 지표 | E28: 관리체계 | F28: 체크리스트 | G28: 운영단계
A29: 적시성 (Timeliness) | B29: 사용자가 원하는 시점에 데이터의 주기에 따른 가장 최신 데이터를 유지하는지 진단하는 지표 | C29: 데이터 최신성 | D29: 데이터의 수집, 갱신 주기에 따라 최신의 값을 유지하는지 진단하는 지표 | E29: 관리체계 | F29: 체크리스트 | G29: 운영단계
A30: ※ 기타사항 ①[NIA]데이터 품질지표를 기본으로 2023년 공공데이터 품질관리 수준진단·평가 매뉴얼의 붙임2 DB대상을 참고하여 추가/변경함 ②진단유형 선정기준 - 컬럼 영문명/도메인명 ③코드진단은 코드테이블(예: COM_CODE)을 사용하고 개별 병원 정책(명명규칙/코드정책 등)에 따라 정의가능(단, 모든 코드값/코드명은 DB입력 필요) ④(기타)업무규칙 - 진단유형에 포함되지 않는 경우 별도의 진단SQL 추가(향후 진행예정)

Sheet Ⅱ.품질진단 테이블
A1: ※ 최종 수정일자(2024-08-06)
A2: 테이블 정보 | K2: 진단 정보
A3: 대분류 | B3: 버전 | C3: 테이블순번 | D3: 주제분류 | E3: 한글테이블명 | F3: 영문테이블명 | G3: 적재기간 | H3: 수집기준일자 컬럼명 | I3: 수집기준일자 영문컬럼명 | J3: 컬럼 수 | K3: 진단대상여부 | L3: 대상제외사유 | M3: 필수여부 | N3: 진단범위 | O3: DBMS 종류 버전
A4: Baseline DB | B4: 5.3.1 | C4: 1 | D4: Clinical Data | E4: 환자정보 | F4: PERSON | G4: 2010년~현재 | J4: 18 | K4: Y | M4: Y | N4: 전체 | O4: 예)SAP HANA 2.0
A5: Baseline DB | B5: 5.3.1 | C5: 2 | D5: Clinical Data | E5: 관찰기간정보 | F5: OBSERVATION_PERIOD | G5: 2010년~현재 | J5: 5 | K5: Y | M5: Y | N5: 전체 | O5: 예)SAP HANA 2.0
A6: Baseline DB | B6: 5.3.1 | C6: 3 | D6: Clinical Data | E6: 내원정보 | F6: VISIT_OCCURRENCE | G6: 2010년~현재 | J6: 17 | K6: Y | M6: Y | N6: 전체 | O6: 예)SAP HANA 2.0
A7: Baseline DB | B7: 5.3.1 | C7: 4 | D7: Clinical Data | E7: 내원상세 | F7: VISIT_DETAIL | G7: 2010년~현재 | J7: 19 | K7: Y | M7: - | N7: 전체 | O7: 예)SAP HANA 2.0
A8: Baseline DB | B8: 5.3.1 | C8: 5 | D8: Clinical Data | E8: 진단정보 | F8: CONDITION_OCCURRENCE | G8: 2010년~현재 | J8: 16 | K8: Y | M8: Y | N8: 전체 | O8: 예)SAP HANA 2.0
A9: Baseline DB | B9: 5.3.1 | C9: 6 | D9: Clinical Data | E9: 투약정보 | F9: DRUG_EXPOSURE | G9: 2010년~현재 | J9: 23 | K9: Y | M9: Y | N9: 전체 | O9: 예)SAP HANA 2.0
A10: Baseline DB | B10: 5.3.1 | C10: 7 | D10: Clinical Data | E10: 수술처치정보 | F10: PROCEDURE_OCCURRENCE | G10: 2010년~현재 | J10: 14 | K10: Y | M10: Y | N10: 전체 | O10: 예)SAP HANA 2.0
A11: Baseline DB | B11: 5.3.1 | C11: 8 | D11: Clinical Data | E11: 처치재료 | F11: DEVICE_EXPOSURE | G11: 2010년~현재 | J11: 15 | K11: Y | M11: - | N11: 전체 | O11: 예)SAP HANA 2.0
A12: Baseline DB | B12: 5.3.1 | C12: 9 | D12: Clinical Data | E12: 검사정보 | F12: MEASUREMENT | G12: 2010년~현재 | J12: 20 | K12: Y | M12: Y | N12: 전체 | O12: 예)SAP HANA 2.0
A13: Baseline DB | B13: 5.3.1 | C13: 10 | D13: Clinical Data | E13: 관찰정보 | F13: OBSERVATION | G13: 2010년~현재 | J13: 18 | K13: Y | M13: Y | N13: 전체 | O13: 예)SAP HANA 2.0
A14: Baseline DB | B14: 5.3.1 | C14: 11 | D14: Clinical Data | E14: 사망정보 | F14: DEATH | G14: 2010년~현재 | J14: 7 | K14: Y | M14: Y | N14: 전체 | O14: 예)SAP HANA 2.0
A15: Baseline DB | B15: 5.3.1 | C15: 12 | D15: Clinical Data | E15: 기록정보 | F15: NOTE | G15: 2010년~현재 | J15: 14 | K15: Y | M15: Y | N15: 전체 | O15: 예)SAP HANA 2.0
... A17: Baseline DB | B17: 5.3.1 | C17: 14 | D17: Clinical Data | E17: 인체유래물정보 | F17: SPECIMEN | G17: 2010년~현재 | J17: 15 | K17: Y | M17: - | N17: 전체 | O17: 예)SAP HANA 2.0
A18: Baseline DB | B18: 5.4 | C18: 1 | D18: Clinical Data | E18: 환자정보 | F18: PERSON | G18: 2010년~현재 | J18: 18 | K18: Y | M18: Y | N18: 전체 | O18: 예)SAP HANA 2.0
A19: Baseline DB | B19: 5.4 | C19: 2 | D19: Clinical Data | E19: 관찰기간정보 | F19: OBSERVATION_PERIOD | G19: 2010년~현재 | J19: 5 | K19: Y | M19: Y | N19: 전체 | O19: 예)SAP HANA 2.0
A20: Baseline DB | B20: 5.4 | C20: 3 | D20: Clinical Data | E20: 내원정보 | F20: VISIT_OCCURRENCE | G20: 2010년~현재 | J20: 17 | K20: Y | M20: Y | N20: 전체 | O20: 예)SAP HANA 2.0
A21: Baseline DB | B21: 5.4 | C21: 4 | D21: Clinical Data | E21: 내원상세 | F21: VISIT_DETAIL | G21: 2010년~현재 | J21: 19 | K21: Y | M21: - | N21: 전체 | O21: 예)SAP HANA 2.0
A22: Baseline DB | B22: 5.4 | C22: 5 | D22: Clinical Data | E22: 진단정보 | F22: CONDITION_OCCURRENCE | G22: 2010년~현재 | J22: 16 | K22: Y | M22: Y | N22: 전체 | O22: 예)SAP HANA 2.0
A23: Baseline DB | B23: 5.4 | C23: 6 | D23: Clinical Data | E23: 투약정보 | F23: DRUG_EXPOSURE | G23: 2010년~현재 | J23: 23 | K23: Y | M23: Y | N23: 전체 | O23: 예)SAP HANA 2.0
A24: Baseline DB | B24: 5.4 | C24: 7 | D24: Clinical Data | E24: 수술처치정보 | F24: PROCEDURE_OCCURRENCE | G24: 2010년~현재 | J24: 16 | K24: Y | M24: Y | N24: 전체 | O24: 예)SAP HANA 2.0
A25: Baseline DB | B25: 5.4 | C25: 8 | D25: Clinical Data | E25: 처치재료 | F25: DEVICE_EXPOSURE | G25: 2010년~현재 | J25: 19 | K25: Y | M25: - | N25: 전체 | O25: 예)SAP HANA 2.0
A26: Baseline DB | B26: 5.4 | C26: 9 | D26: Clinical Data | E26: 검사정보 | F26: MEASUREMENT | G26: 2010년~현재 | J26: 23 | K26: Y | M26: Y | N26: 전체 | O26: 예)SAP HANA 2.0
A27: Baseline DB | B27: 5.4 | C27: 10 | D27: Clinical Data | E27: 관찰정보 | F27: OBSERVATION | G27: 2010년~현재 | J27: 21 | K27: Y | M27: Y | N27: 전체 | O27: 예)SAP HANA 2.0
A28: Baseline DB | B28: 5.4 | C28: 11 | D28: Clinical Data | E28: 사망정보 | F28: DEATH | G28: 2010년~현재 | J28: 7 | K28: Y | M28: Y | N28: 전체 | O28: 예)SAP HANA 2.0
A29: Baseline DB | B29: 5.4 | C29: 12 | D29: Clinical Data | E29: 기록정보 | F29: NOTE | G29: 2010년~현재 | J29: 16 | K29: Y | M29: Y | N29: 전체 | O29: 예)SAP HANA 2.0
... A31: Baseline DB | B31: 5.4 | C31: 14 | D31: Clinical Data | E31: 인체유래물정보 | F31: SPECIMEN | G31: 2010년~현재 | J31: 15 | K31: Y | M31: - | N31: 전체 | O31: 예)SAP HANA 2.0

Sheet Ⅲ.품질진단 컬럼_규칙_결과
P1: 항목정의서 정보 | S1: 2. 진단규칙 정의 | AP1: SAP HANA | AY1: MSSQL | BH1: postgreSQL | BQ1: MariaDB | BZ1: oracle | CI1: Sybase IQ(확인필요) | CR1: 3.진단 결과 | CV1: 수집동의
A2: 버전 | B2: 대분류 | C2: 스키마명 | D2: 테이블순번 | E2: 주제분류 | F2: 한글테이블명 | G2: 영문테이블명 | H2: 컬럼순번 | I2: 한글컬럼명 | J2: 영문컬럼명 | K2: 데이터타입 | L2: PK | M2: 도메인명 | N2: 설명 | O2: 값 | P2: 항목명 | Q2: 비고 | R2: NULL 여부 | S2: 진단기준 | T2: 공통항목 여부 | U2: 진단NO | V2: 진단대상 여부 | W2: 진단대상 제외사유/특이사항 | X2: 진단방법 | Y2: 업무규칙ID | Z2: 상세지표 | AA2: 진단유형 | AB2: CD_CLCD ( 코드분류코드) | AC2: CD_ID (코드ID) | AD2: CD_NM (관련코드그룹컬럼명) | AE2: 코드명 관리여부 | AF2: 코드테이블 스키마명 | AG2: 코드테이블 | AH2: 코드명 (참조) | AI2: 코드값 (참조) | AJ2: 참조테이블명 | AK2: 참조컬럼명 | AL2: 최소값 | AM2: 최대값 | AN2: 진단규칙 내용 | AO2: 오류제외 데이터 (기본값) | AP2: 총건수 | AQ2: UNION ALL | AR2: 프로시저 | AS2: 오류건수 | AT2: UNION ALL | AU2: 프로시저 | AV2: 오류데이터 | AW2: UNION ALL | AX2: 프로시저 | AY2: 총건수 | AZ2: UNION ALL | BA2: 프로시저 | BB2: 오류건수 | BC2: UNION ALL | BD2: 프로시저 | BE2: 오류데이터 | BF2: UNION ALL | BG2: 프로시저 | BH2: 총건수 | BI2: UNION ALL | BJ2: 프로시저 | BK2: 오류건수 | BL2: UNION ALL | BM2: 프로시저 | BN2: 오류데이터 | BO2: UNION ALL | BP2: 프로시저 | BQ2: 총건수 | BR2: UNION ALL | BS2: 프로시저 | BT2: 오류건수 | BU2: UNION ALL | BV2: 프로시저 | BW2: 오류데이터 | BX2: UNION ALL | BY2: 프로시저 | BZ2: 총건수 | CA2: UNION ALL | CB2: 프로시저 | CC2: 오류건수 | CD2: UNION ALL | CE2: 프로시저 | CF2: 오류데이터 | CG2: UNION ALL | CH2: 프로시저 | CI2: 총건수 | CJ2: UNION ALL | CK2: 프로시저 | CL2: 오류건수 | CM2: UNION ALL | CN2: 프로시저 | CO2: 오류데이터 | CP2: UNION ALL | CQ2: 프로시저 | CR2: 총건수 | CS2: 오류건수 | CT2: 오류율(%) | CU2: 오류데이터(최대 3개)
A3: 5.3.1 | B3: Baseline DB | C3: YourSchemaName | D3: 1 | E3: Clinical Data | F3: 환자정보 | G3: PERSON | H3: 1 | I3: CDM 환자ID | J3: PERSON_ID | K3: INTEGER | L3: PK | N3: CDM 환자ID | O3: 100000001 | Q3: 필수 | R3: NOT NULL | V3: N | W3: 숫자형 일련번호 | CR3: =IFERROR(VLOOKUP("ID"&U3,V.진단결과!$A$2:$E$99558,4,0),0) -> 0 | CS3: =IFERROR(VLOOKUP("ID"&U3,V.진단결과!$A$2:$E$99558,5,0),0) -> 0 | CT3: =IFERROR(CS3/CR3,0) -> 0 | CU3: =SUBSTITUTE(IFERROR(VLOOKUP("ID"&U3,V.진단결과!$A$2:$F$99558,6,0),""),$AO3,"")
